<?xml version="1.0" encoding="UTF-8"?>
<!-- Generated by org.testng.reporters.JUnitXMLReporter -->
<testsuite ignored="0" hostname="DESKTOP-BU76AG9" failures="2" tests="9" name="Default test" time="18.852" errors="0" timestamp="2024-07-29T17:13:08 IST">
  <testcase classname="sample.Product.ProductsListTest" name="testContentType" time="5.085"/>
  <testcase classname="sample.Product.ProductsListTest" name="testFilterByCategory" time="2.814">
    <failure type="java.lang.AssertionError" message="No products found for the category expected [false] but found [true]">
      <![CDATA[java.lang.AssertionError: No products found for the category expected [false] but found [true]
at org.testng.Assert.fail(Assert.java:110)
at org.testng.Assert.failNotEquals(Assert.java:1577)
at org.testng.Assert.assertFalse(Assert.java:78)
at sample.Product.ProductsListTest.testFilterByCategory(ProductsListTest.java:87)
at java.base/jdk.internal.reflect.DirectMethodHandleAccessor.invoke(DirectMethodHandleAccessor.java:103)
at java.base/java.lang.reflect.Method.invoke(Method.java:580)
at org.testng.internal.invokers.MethodInvocationHelper.invokeMethod(MethodInvocationHelper.java:139)
at org.testng.internal.invokers.TestInvoker.invokeMethod(TestInvoker.java:677)
at org.testng.internal.invokers.TestInvoker.invokeTestMethod(TestInvoker.java:221)
at org.testng.internal.invokers.MethodRunner.runInSequence(MethodRunner.java:50)
at org.testng.internal.invokers.TestInvoker$MethodInvocationAgent.invoke(TestInvoker.java:969)
at org.testng.internal.invokers.TestInvoker.invokeTestMethods(TestInvoker.java:194)
at org.testng.internal.invokers.TestMethodWorker.invokeTestMethods(TestMethodWorker.java:148)
at org.testng.internal.invokers.TestMethodWorker.run(TestMethodWorker.java:128)
at java.base/java.util.ArrayList.forEach(ArrayList.java:1597)
at org.testng.TestRunner.privateRun(TestRunner.java:829)
at org.testng.TestRunner.run(TestRunner.java:602)
at org.testng.SuiteRunner.runTest(SuiteRunner.java:437)
at org.testng.SuiteRunner.runSequentially(SuiteRunner.java:431)
at org.testng.SuiteRunner.privateRun(SuiteRunner.java:391)
at org.testng.SuiteRunner.run(SuiteRunner.java:330)
at org.testng.SuiteRunnerWorker.runSuite(SuiteRunnerWorker.java:52)
at org.testng.SuiteRunnerWorker.run(SuiteRunnerWorker.java:95)
at org.testng.TestNG.runSuitesSequentially(TestNG.java:1256)
at org.testng.TestNG.runSuitesLocally(TestNG.java:1176)
at org.testng.TestNG.runSuites(TestNG.java:1099)
at org.testng.TestNG.run(TestNG.java:1067)
at org.testng.remote.AbstractRemoteTestNG.run(AbstractRemoteTestNG.java:115)
at org.testng.remote.RemoteTestNG.initAndRun(RemoteTestNG.java:293)
at org.testng.remote.RemoteTestNG.main(RemoteTestNG.java:91)
]]>
    </failure>
  </testcase> <!-- testFilterByCategory -->
  <testcase classname="sample.Product.ProductsListTest" name="testGetAllProductsListSuccess" time="1.233"/>
  <testcase classname="sample.Product.ProductsListTest" name="testInvalidEndpoint" time="1.234">
    <failure type="io.restassured.path.json.exception.JsonPathException" message="Failed to parse the JSON document">
      <![CDATA[io.restassured.path.json.exception.JsonPathException: Failed to parse the JSON document
at io.restassured.path.json.JsonPath$ExceptionCatcher.invoke(JsonPath.java:1002)
at io.restassured.path.json.JsonPath$4.doParseWith(JsonPath.java:967)
at io.restassured.path.json.JsonPath$JsonParser.parseWith(JsonPath.java:1047)
at io.restassured.path.json.JsonPath.get(JsonPath.java:202)
at io.restassured.path.json.JsonPath.getInt(JsonPath.java:237)
at sample.Product.ProductsListTest.testInvalidEndpoint(ProductsListTest.java:96)
at java.base/jdk.internal.reflect.DirectMethodHandleAccessor.invoke(DirectMethodHandleAccessor.java:103)
at java.base/java.lang.reflect.Method.invoke(Method.java:580)
at org.testng.internal.invokers.MethodInvocationHelper.invokeMethod(MethodInvocationHelper.java:139)
at org.testng.internal.invokers.TestInvoker.invokeMethod(TestInvoker.java:677)
at org.testng.internal.invokers.TestInvoker.invokeTestMethod(TestInvoker.java:221)
at org.testng.internal.invokers.MethodRunner.runInSequence(MethodRunner.java:50)
at org.testng.internal.invokers.TestInvoker$MethodInvocationAgent.invoke(TestInvoker.java:969)
at org.testng.internal.invokers.TestInvoker.invokeTestMethods(TestInvoker.java:194)
at org.testng.internal.invokers.TestMethodWorker.invokeTestMethods(TestMethodWorker.java:148)
at org.testng.internal.invokers.TestMethodWorker.run(TestMethodWorker.java:128)
at java.base/java.util.ArrayList.forEach(ArrayList.java:1597)
at org.testng.TestRunner.privateRun(TestRunner.java:829)
at org.testng.TestRunner.run(TestRunner.java:602)
at org.testng.SuiteRunner.runTest(SuiteRunner.java:437)
at org.testng.SuiteRunner.runSequentially(SuiteRunner.java:431)
at org.testng.SuiteRunner.privateRun(SuiteRunner.java:391)
at org.testng.SuiteRunner.run(SuiteRunner.java:330)
at org.testng.SuiteRunnerWorker.runSuite(SuiteRunnerWorker.java:52)
at org.testng.SuiteRunnerWorker.run(SuiteRunnerWorker.java:95)
at org.testng.TestNG.runSuitesSequentially(TestNG.java:1256)
at org.testng.TestNG.runSuitesLocally(TestNG.java:1176)
at org.testng.TestNG.runSuites(TestNG.java:1099)
at org.testng.TestNG.run(TestNG.java:1067)
at org.testng.remote.AbstractRemoteTestNG.run(AbstractRemoteTestNG.java:115)
at org.testng.remote.RemoteTestNG.initAndRun(RemoteTestNG.java:293)
at org.testng.remote.RemoteTestNG.main(RemoteTestNG.java:91)
Caused by: groovy.json.JsonException: Lexing failed on line: 1, column: 1, while reading '<', no possible valid JSON value or punctuation could be recognized.
at groovy.json.JsonLexer.nextToken(JsonLexer.java:86)
at groovy.json.JsonLexer$nextToken.call(Unknown Source)
at io.restassured.internal.path.json.ConfigurableJsonSlurper.parse(ConfigurableJsonSlurper.groovy:97)
at io.restassured.internal.path.json.ConfigurableJsonSlurper$parse.callCurrent(Unknown Source)
at io.restassured.internal.path.json.ConfigurableJsonSlurper.parseText(ConfigurableJsonSlurper.groovy:83)
at io.restassured.path.json.JsonPath$4$1.method(JsonPath.java:965)
at io.restassured.path.json.JsonPath$ExceptionCatcher.invoke(JsonPath.java:1000)
... 31 more
]]>
    </failure>
  </testcase> <!-- testInvalidEndpoint -->
  <testcase classname="sample.Product.ProductsListTest" name="testProductStructure" time="1.392"/>
  <testcase classname="sample.Product.ProductsListTest" name="testResponseContainsProducts" time="1.326"/>
  <testcase classname="sample.Product.ProductsListTest" name="testResponseTime" time="1.183"/>
  <testcase classname="sample.Product.ProductsListTest" name="testSpecificProductDetails" time="1.372"/>
  <testcase classname="sample.Product.ProductsListTest" name="testUnsupportedMethod" time="1.22"/>
</testsuite> <!-- Default test -->
